Workbook

Sheet Entregas
A1: ID | B1: Nº | C1: CLIENTE | D1: OPERACIÓN | E1: DESPACHO | F1: CONTENEDOR | G1: TIPO | H1: PESO | I1: LUGAR RETIRO | J1: FECHA ENTREGA | K1: HORA ENTREGA | L1: Ubicación Vacio | M1: CONDUCTOR | N1: CONTACTO | O1: EQUIPO | P1: Rampla | Q1: Dirección Entrega | R1: DEPOSITO DEVOLUCION | S1: Conductor Devolución | T1: Equipo Devolución | U1: Fecha devolución | V1: Estado Devolución | W1: FOLIO | X1: NOTA | Y1: Estado de entrega | Z1: RC_NE | AA1: Hora Real Entrega | AB1: Hora Salida | AC1: Fecha Real Entrega | AD1: OTD | AE1: Validador | AF1: Mensaje | AG1: Link | AH1: Validador2 | AI1: Op | AJ1: VAL | AK1: Concat | AL1: URL
A2: =ROW(A1) -> 1 | B2: =IF(J2=J1,B1+1,1) -> 1 | C2: EL CONTAINER SPA | D2: IMPO | E2: 303965 | F2: CAAU4530857 | G2: 40 HC | H2: 26800 | I2: FRAGUA | J2: 46028 | N2: =IFERROR(VLOOKUP(M2,Data!$J$1:$K$58,2,0),"") | AD2: =IF(Tabla2[[#This Row],[HORA ENTREGA]]="DIRECTO","On time", IF(AA2<>"",IF(Tabla2[[#This Row],[Fecha Real Entrega]]<Tabla2[[#This Row],[FECHA ENTREGA]],"On time",IF(Tabla2[[#This Row],[Hora Real Entrega]]<=Tabla2[[#This Row],[HORA ENTREGA]]+(15/1440),"On time","Off time")),"Sin llegada")) -> Sin llegada | AE2: =MID(Tabla2[[#This Row],[TIPO]],1,3) -> 40 | AF2: ="Hola!" & "%0A" & "Servicio del día " &TEXT(Tabla2[[#This Row],[FECHA ENTREGA]],"dd-mm") & "%0A" & " *Cliente:* " &Tabla2[[#This Row],[CLIENTE]] & " */ Cont: * "&Tabla2[[#This Row],[CONTENEDOR]] & "*/ HR Entrega: *" & TEXT(Tabla2[[#This Row],[HORA ENTREGA]],"hh:mm") & "* /Dirección: *" & Tabla2[[#This Row],[Dirección Entrega]] -> Hola!%0AServicio del día 06-01%0A *Cliente:* EL CONTAINER SPA */ Cont: * CAAU4530857*/ HR Entrega: *00:00* /Dirección: * | AG2: =IFERROR(HYPERLINK("https://wa.me/"&Tabla2[[#This Row],[CONTACTO]]&"?text="&Tabla2[[#This Row],[Mensaje]],"Enviar mensaje"),"") -> Enviar mensaje | AH2: =CONCATENATE(A2,F2) -> 1CAAU4530857 | AI2: =CONCATENATE("ENT-",A2) -> ENT-1 | AJ2: =IF(Tabla2[[#This Row],[Op]]<>"","ENTREGA","") -> ENTREGA | AK2: =(Tabla2[[#This Row],[FECHA ENTREGA]]&Tabla2[[#This Row],[HORA ENTREGA]]) -> 46028 | AL2: =IFERROR(HYPERLINK("https://wa.me/"&Tabla2[[#This Row],[CONTACTO]]&"?text="&Tabla2[[#This Row],[Mensaje]]),"") -> https://wa.me/?text=Hola!%0AServicio del día 06-01%0A *Cliente:* EL CONTAINER SPA */ Cont: * CAAU4530857*/ HR Entrega: *00:00* /Dirección: *
A3: =ROW(A2) -> 2 | B3: =IF(J3=J2,B2+1,1) -> 1 | C3: ALCA SPA | D3: IMPO | E3: 297289 | F3: CGMU5741499 | G3: 40 HC | H3: 32000 | I3: FRAGUA | J3: 46055 | K3: 0.33333333 | M3: SAMUEL SALAS | N3: =IFERROR(VLOOKUP(M3,Data!$J$1:$K$58,2,0),"") -> 56950981572 | O3: THYG-63 | Q3: BERNARDO O"HIGGINS 158 COLINA | R3: CIS | Y3: ENTREGADO | AA3: 0.33333333 | AC3: 46055 | AD3: =IF(Tabla2[[#This Row],[HORA ENTREGA]]="DIRECTO","On time", IF(AA3<>"",IF(Tabla2[[#This Row],[Fecha Real Entrega]]<Tabla2[[#This Row],[FECHA ENTREGA]],"On time",IF(Tabla2[[#This Row],[Hora Real Entrega]]<=Tabla2[[#This Row],[HORA ENTREGA]]+(15/1440),"On time","Off time")),"Sin llegada")) -> On time | AE3: =MID(Tabla2[[#This Row],[TIPO]],1,3) -> 40 | AF3: ="Hola!" & "%0A" & "Servicio del día " &TEXT(Tabla2[[#This Row],[FECHA ENTREGA]],"dd-mm") & "%0A" & " *Cliente:* " &Tabla2[[#This Row],[CLIENTE]] & " */ Cont: * "&Tabla2[[#This Row],[CONTENEDOR]] & "*/ HR Entrega: *" & TEXT(Tabla2[[#This Row],[HORA ENTREGA]],"hh:mm") & "* /Dirección: *" & Tabla2[[#This Row],[Dirección Entrega]] -> Hola!%0AServicio del día 02-02%0A *Cliente:* ALCA SPA */ Cont: * CGMU5741499*/ HR Entrega: *08:00* /Dirección: *BERNARDO O"HIGGINS 158 COLINA | AG3: =IFERROR(HYPERLINK("https://wa.me/"&Tabla2[[#This Row],[CONTACTO]]&"?text="&Tabla2[[#This Row],[Mensaje]],"Enviar mensaje"),"") -> Enviar mensaje | AH3: =CONCATENATE(A3,F3) -> 2CGMU5741499 | AI3: =CONCATENATE("ENT-",A3) -> ENT-2 | AJ3: =IF(Tabla2[[#This Row],[Op]]<>"","ENTREGA","") -> ENTREGA | AK3: =(Tabla2[[#This Row],[FECHA ENTREGA]]&Tabla2[[#This Row],[HORA ENTREGA]]) -> 460550,333333333333333 | AL3: =IFERROR(HYPERLINK("https://wa.me/"&Tabla2[[#This Row],[CONTACTO]]&"?text="&Tabla2[[#This Row],[Mensaje]]),"") -> https://wa.me/56950981572?text=Hola!%0AServicio del día 02-02%0A *Cliente:* ALCA SPA */ Cont: * CGMU5741499*/ HR Entrega: *08:00* /Dirección: *BERNARDO O"HIGGINS 158 COLINA
A4: =ROW(A3) -> 3 | B4: =IF(J4=J3,B3+1,1) -> 2 | C4: ALCA SPA | D4: IMPO | E4: 297289 | F4: SEGU9527603 | G4: 40 HC | H4: 32000 | I4: FRAGUA | J4: 46055 | K4: 0.41666667 | M4: HELBERTH CASTRO | N4: =IFERROR(VLOOKUP(M4,Data!$J$1:$K$58,2,0),"") -> 56967256951 | O4: RFZW-96 | Q4: BERNARDO O"HIGGINS 158 COLINA | R4: CIS | Y4: ENTREGADO | AA4: 0.39930556 | AC4: 46055 | AD4: =IF(Tabla2[[#This Row],[HORA ENTREGA]]="DIRECTO","On time", IF(AA4<>"",IF(Tabla2[[#This Row],[Fecha Real Entrega]]<Tabla2[[#This Row],[FECHA ENTREGA]],"On time",IF(Tabla2[[#This Row],[Hora Real Entrega]]<=Tabla2[[#This Row],[HORA ENTREGA]]+(15/1440),"On time","Off time")),"Sin llegada")) -> On time | AE4: =MID(Tabla2[[#This Row],[TIPO]],1,3) -> 40 | AF4: ="Hola!" & "%0A" & "Servicio del día " &TEXT(Tabla2[[#This Row],[FECHA ENTREGA]],"dd-mm") & "%0A" & " *Cliente:* " &Tabla2[[#This Row],[CLIENTE]] & " */ Cont: * "&Tabla2[[#This Row],[CONTENEDOR]] & "*/ HR Entrega: *" & TEXT(Tabla2[[#This Row],[HORA ENTREGA]],"hh:mm") & "* /Dirección: *" & Tabla2[[#This Row],[Dirección Entrega]] -> Hola!%0AServicio del día 02-02%0A *Cliente:* ALCA SPA */ Cont: * SEGU9527603*/ HR Entrega: *10:00* /Dirección: *BERNARDO O"HIGGINS 158 COLINA | AG4: =IFERROR(HYPERLINK("https://wa.me/"&Tabla2[[#This Row],[CONTACTO]]&"?text="&Tabla2[[#This Row],[Mensaje]],"Enviar mensaje"),"") -> Enviar mensaje | AH4: =CONCATENATE(A4,F4) -> 3SEGU9527603 | AI4: =CONCATENATE("ENT-",A4) -> ENT-3 | AJ4: =IF(Tabla2[[#This Row],[Op]]<>"","ENTREGA","") -> ENTREGA | AK4: =(Tabla2[[#This Row],[FECHA ENTREGA]]&Tabla2[[#This Row],[HORA ENTREGA]]) -> 460550,416666666666667 | AL4: =IFERROR(HYPERLINK("https://wa.me/"&Tabla2[[#This Row],[CONTACTO]]&"?text="&Tabla2[[#This Row],[Mensaje]]),"") -> https://wa.me/56967256951?text=Hola!%0AServicio del día 02-02%0A *Cliente:* ALCA SPA */ Cont: * SEGU9527603*/ HR Entrega: *10:00* /Dirección: *BERNARDO O"HIGGINS 158 COLINA
A5: =ROW(A4) -> 4 | B5: =IF(J5=J4,B4+1,1) -> 3 | C5: ALCA SPA | D5: IMPO | E5: 366856 | F5: HLBU9689467 | G5: 40 RF | H5: 20000 | I5: 46053 | J5: 46055 | K5: 0.47916667 | M5: RODRIGO AÑAZCO | N5: =IFERROR(VLOOKUP(M5,Data!$J$1:$K$58,2,0),"") -> 56992164782 | O5: LGGR-14 | Q5: Camino del Cerro 4868 Huechuraba | R5: DYC VALP | Y5: ENTREGADO | AA5: 0.51388889 | AC5: 46055 | AD5: =IF(Tabla2[[#This Row],[HORA ENTREGA]]="DIRECTO","On time", IF(AA5<>"",IF(Tabla2[[#This Row],[Fecha Real Entrega]]<Tabla2[[#This Row],[FECHA ENTREGA]],"On time",IF(Tabla2[[#This Row],[Hora Real Entrega]]<=Tabla2[[#This Row],[HORA ENTREGA]]+(15/1440),"On time","Off time")),"Sin llegada")) -> Off time | AE5: =MID(Tabla2[[#This Row],[TIPO]],1,3) -> 40 | AF5: ="Hola!" & "%0A" & "Servicio del día " &TEXT(Tabla2[[#This Row],[FECHA ENTREGA]],"dd-mm") & "%0A" & " *Cliente:* " &Tabla2[[#This Row],[CLIENTE]] & " */ Cont: * "&Tabla2[[#This Row],[CONTENEDOR]] & "*/ HR Entrega: *" & TEXT(Tabla2[[#This Row],[HORA ENTREGA]],"hh:mm") & "* /Dirección: *" & Tabla2[[#This Row],[Dirección Entrega]] -> Hola!%0AServicio del día 02-02%0A *Cliente:* ALCA SPA */ Cont: * HLBU9689467*/ HR Entrega: *11:30* /Dirección: *Camino del Cerro 4868 Huechuraba | AG5: =IFERROR(HYPERLINK("https://wa.me/"&Tabla2[[#This Row],[CONTACTO]]&"?text="&Tabla2[[#This Row],[Mensaje]],"Enviar mensaje"),"") -> Enviar mensaje | AH5: =CONCATENATE(A5,F5) -> 4HLBU9689467 | AI5: =CONCATENATE("ENT-",A5) -> ENT-4 | AJ5: =IF(Tabla2[[#This Row],[Op]]<>"","ENTREGA","") -> ENTREGA | AK5: =(Tabla2[[#This Row],[FECHA ENTREGA]]&Tabla2[[#This Row],[HORA ENTREGA]]) -> 460550,479166666666667 | AL5: =IFERROR(HYPERLINK("https://wa.me/"&Tabla2[[#This Row],[CONTACTO]]&"?text="&Tabla2[[#This Row],[Mensaje]]),"") -> https://wa.me/56992164782?text=Hola!%0AServicio del día 02-02%0A *Cliente:* ALCA SPA */ Cont: * HLBU9689467*/ HR Entrega: *11:30* /Dirección: *Camino del Cerro 4868 Huechuraba
A6: =ROW(A5) -> 5 | B6: =IF(J6=J5,B5+1,1) -> 4 | C6: ALCA SPA | D6: IMPO | E6: 297289 | F6: CGMU5298919 | G6: 40 HC | H6: 32000 | I6: FRAGUA | J6: 46055 | K6: 0.5 | M6: FELIPE CATALAN | N6: =IFERROR(VLOOKUP(M6,Data!$J$1:$K$58,2,0),"") -> 56957438415 | O6: RRVF-72 | Q6: BERNARDO O"HIGGINS 158 COLINA | R6: CIS | Y6: ENTREGADO | AA6: 0.55694444 | AC6: 46055 | AD6: =IF(Tabla2[[#This Row],[HORA ENTREGA]]="DIRECTO","On time", IF(AA6<>"",IF(Tabla2[[#This Row],[Fecha Real Entrega]]<Tabla2[[#This Row],[FECHA ENTREGA]],"On time",IF(Tabla2[[#This Row],[Hora Real Entrega]]<=Tabla2[[#This Row],[HORA ENTREGA]]+(15/1440),"On time","Off time")),"Sin llegada")) -> Off time | AE6: =MID(Tabla2[[#This Row],[TIPO]],1,3) -> 40 | AF6: ="Hola!" & "%0A" & "Servicio del día " &TEXT(Tabla2[[#This Row],[FECHA ENTREGA]],"dd-mm") & "%0A" & " *Cliente:* " &Tabla2[[#This Row],[CLIENTE]] & " */ Cont: * "&Tabla2[[#This Row],[CONTENEDOR]] & "*/ HR Entrega: *" & TEXT(Tabla2[[#This Row],[HORA ENTREGA]],"hh:mm") & "* /Dirección: *" & Tabla2[[#This Row],[Dirección Entrega]] -> Hola!%0AServicio del día 02-02%0A *Cliente:* ALCA SPA */ Cont: * CGMU5298919*/ HR Entrega: *12:00* /Dirección: *BERNARDO O"HIGGINS 158 COLINA | AG6: =IFERROR(HYPERLINK("https://wa.me/"&Tabla2[[#This Row],[CONTACTO]]&"?text="&Tabla2[[#This Row],[Mensaje]],"Enviar mensaje"),"") -> Enviar mensaje | AH6: =CONCATENATE(A6,F6) -> 5CGMU5298919 | AI6: =CONCATENATE("ENT-",A6) -> ENT-5 | AJ6: =IF(Tabla2[[#This Row],[Op]]<>"","ENTREGA","") -> ENTREGA | AK6: =(Tabla2[[#This Row],[FECHA ENTREGA]]&Tabla2[[#This Row],[HORA ENTREGA]]) -> 460550,5 | AL6: =IFERROR(HYPERLINK("https://wa.me/"&Tabla2[[#This Row],[CONTACTO]]&"?text="&Tabla2[[#This Row],[Mensaje]]),"") -> https://wa.me/56957438415?text=Hola!%0AServicio del día 02-02%0A *Cliente:* ALCA SPA */ Cont: * CGMU5298919*/ HR Entrega: *12:00* /Dirección: *BERNARDO O"HIGGINS 158 COLINA
A7: =ROW(A6) -> 6 | B7: =IF(J7=J6,B6+1,1) -> 5 | C7: BATERIAS TUBULAR S.A. | D7: IMPO | E7: 297933 | F7: FTAU2361050 | G7: 20 DV | H7: 6000 | I7: 31/01 - 11:14 | J7: 46055 | K7: 0.33333333 | M7: DANIEL GOMEZ | N7: =IFERROR(VLOOKUP(M7,Data!$J$1:$K$58,2,0),"") -> 56993389870 | O7: LPYG-89 | Q7: AV. CHENA PONIENTE 12624, SAN BERNARDO | R7: DYC SAI | Y7: ENTREGADO | AA7: 0.29513889 | AC7: 46055 | AD7: =IF(Tabla2[[#This Row],[HORA ENTREGA]]="DIRECTO","On time", IF(AA7<>"",IF(Tabla2[[#This Row],[Fecha Real Entrega]]<Tabla2[[#This Row],[FECHA ENTREGA]],"On time",IF(Tabla2[[#This Row],[Hora Real Entrega]]<=Tabla2[[#This Row],[HORA ENTREGA]]+(15/1440),"On time","Off time")),"Sin llegada")) -> On time | AE7: =MID(Tabla2[[#This Row],[TIPO]],1,3) -> 20 | AF7: ="Hola!" & "%0A" & "Servicio del día " &TEXT(Tabla2[[#This Row],[FECHA ENTREGA]],"dd-mm") & "%0A" & " *Cliente:* " &Tabla2[[#This Row],[CLIENTE]] & " */ Cont: * "&Tabla2[[#This Row],[CONTENEDOR]] & "*/ HR Entrega: *" & TEXT(Tabla2[[#This Row],[HORA ENTREGA]],"hh:mm") & "* /Dirección: *" & Tabla2[[#This Row],[Dirección Entrega]] -> Hola!%0AServicio del día 02-02%0A *Cliente:* BATERIAS TUBULAR S.A. */ Cont: * FTAU2361050*/ HR Entrega: *08:00* /Dirección: *AV. CHENA PONIENTE 12624, SAN BERNARDO | AG7: =IFERROR(HYPERLINK("https://wa.me/"&Tabla2[[#This Row],[CONTACTO]]&"?text="&Tabla2[[#This Row],[Mensaje]],"Enviar mensaje"),"") -> Enviar mensaje | AH7: =CONCATENATE(A7,F7) -> 6FTAU2361050 | AI7: =CONCATENATE("ENT-",A7) -> ENT-6 | AJ7: =IF(Tabla2[[#This Row],[Op]]<>"","ENTREGA","") -> ENTREGA | AK7: =(Tabla2[[#This Row],[FECHA ENTREGA]]&Tabla2[[#This Row],[HORA ENTREGA]]) -> 460550,333333333333333 | AL7: =IFERROR(HYPERLINK("https://wa.me/"&Tabla2[[#This Row],[CONTACTO]]&"?text="&Tabla2[[#This Row],[Mensaje]]),"") -> https://wa.me/56993389870?text=Hola!%0AServicio del día 02-02%0A *Cliente:* BATERIAS TUBULAR S.A. */ Cont: * FTAU2361050*/ HR Entrega: *08:00* /Dirección: *AV. CHENA PONIENTE 12624, SAN BERNARDO
A8: =ROW(A7) -> 7 | B8: =IF(J8=J7,B7+1,1) -> 6 | C8: BATERIAS TUBULAR S.A. | D8: IMPO | E8: 297464 | F8: BEAU4281752 | G8: 40 HC | H8: 27000 | I8: 31/01 - 9:16 | J8: 46055 | K8: 0.41666667 | M8: JUAN SALINAS | N8: =IFERROR(VLOOKUP(M8,Data!$J$1:$K$58,2,0),"") -> 56978089148 | O8: HSWP-41 | Q8: AV. CHENA PONIENTE 12624, SAN BERNARDO | R8: MEDLOG SAI | Y8: ENTREGADO | AA8: 0.32986111 | AC8: 46055 | AD8: =IF(Tabla2[[#This Row],[HORA ENTREGA]]="DIRECTO","On time", IF(AA8<>"",IF(Tabla2[[#This Row],[Fecha Real Entrega]]<Tabla2[[#This Row],[FECHA ENTREGA]],"On time",IF(Tabla2[[#This Row],[Hora Real Entrega]]<=Tabla2[[#This Row],[HORA ENTREGA]]+(15/1440),"On time","Off time")),"Sin llegada")) -> On time | AE8: =MID(Tabla2[[#This Row],[TIPO]],1,3) -> 40 | AF8: ="Hola!" & "%0A" & "Servicio del día " &TEXT(Tabla2[[#This Row],[FECHA ENTREGA]],"dd-mm") & "%0A" & " *Cliente:* " &Tabla2[[#This Row],[CLIENTE]] & " */ Cont: * "&Tabla2[[#This Row],[CONTENEDOR]] & "*/ HR Entrega: *" & TEXT(Tabla2[[#This Row],[HORA ENTREGA]],"hh:mm") & "* /Dirección: *" & Tabla2[[#This Row],[Dirección Entrega]] -> Hola!%0AServicio del día 02-02%0A *Cliente:* BATERIAS TUBULAR S.A. */ Cont: * BEAU4281752*/ HR Entrega: *10:00* /Dirección: *AV. CHENA PONIENTE 12624, SAN BERNARDO | AG8: =IFERROR(HYPERLINK("https://wa.me/"&Tabla2[[#This Row],[CONTACTO]]&"?text="&Tabla2[[#This Row],[Mensaje]],"Enviar mensaje"),"") -> Enviar mensaje | AH8: =CONCATENATE(A8,F8) -> 7BEAU4281752 | AI8: =CONCATENATE("ENT-",A8) -> ENT-7 | AJ8: =IF(Tabla2[[#This Row],[Op]]<>"","ENTREGA","") -> ENTREGA | AK8: =(Tabla2[[#This Row],[FECHA ENTREGA]]&Tabla2[[#This Row],[HORA ENTREGA]]) -> 460550,416666666666667 | AL8: =IFERROR(HYPERLINK("https://wa.me/"&Tabla2[[#This Row],[CONTACTO]]&"?text="&Tabla2[[#This Row],[Mensaje]]),"") -> https://wa.me/56978089148?text=Hola!%0AServicio del día 02-02%0A *Cliente:* BATERIAS TUBULAR S.A. */ Cont: * BEAU4281752*/ HR Entrega: *10:00* /Dirección: *AV. CHENA PONIENTE 12624, SAN BERNARDO
A9: =ROW(A8) -> 8 | B9: =IF(J9=J8,B8+1,1) -> 7 | C9: BAYONA SPA | D9: IMPO | E9: 297776 | F9: CMAU7238042 | G9: 40 HC | H9: 7000 | I9: FRAGUA | J9: 46055 | K9: 0.33333333 | M9: ROBERTO CARREÑO | N9: =IFERROR(VLOOKUP(M9,Data!$J$1:$K$58,2,0),"") -> 56967384794 | O9: RVFP-32 | Q9: BOULEVAR 1313 BODENOR FLEX CENTER ENEA, PUDAHUEL | R9: CIS | Y9: ENTREGADO | AA9: 0.31944444 | AC9: 46055 | AD9: =IF(Tabla2[[#This Row],[HORA ENTREGA]]="DIRECTO","On time", IF(AA9<>"",IF(Tabla2[[#This Row],[Fecha Real Entrega]]<Tabla2[[#This Row],[FECHA ENTREGA]],"On time",IF(Tabla2[[#This Row],[Hora Real Entrega]]<=Tabla2[[#This Row],[HORA ENTREGA]]+(15/1440),"On time","Off time")),"Sin llegada")) -> On time | AE9: =MID(Tabla2[[#This Row],[TIPO]],1,3) -> 40 | AF9: ="Hola!" & "%0A" & "Servicio del día " &TEXT(Tabla2[[#This Row],[FECHA ENTREGA]],"dd-mm") & "%0A" & " *Cliente:* " &Tabla2[[#This Row],[CLIENTE]] & " */ Cont: * "&Tabla2[[#This Row],[CONTENEDOR]] & "*/ HR Entrega: *" & TEXT(Tabla2[[#This Row],[HORA ENTREGA]],"hh:mm") & "* /Dirección: *" & Tabla2[[#This Row],[Dirección Entrega]] -> Hola!%0AServicio del día 02-02%0A *Cliente:* BAYONA SPA */ Cont: * CMAU7238042*/ HR Entrega: *08:00* /Dirección: * BOULEVAR 1313 BODENOR FLEX CENTER ENEA, PUDAHUEL | AG9: =IFERROR(HYPERLINK("https://wa.me/"&Tabla2[[#This Row],[CONTACTO]]&"?text="&Tabla2[[#This Row],[Mensaje]],"Enviar mensaje"),"") -> Enviar mensaje | AH9: =CONCATENATE(A9,F9) -> 8CMAU7238042 | AI9: =CONCATENATE("ENT-",A9) -> ENT-8 | AJ9: =IF(Tabla2[[#This Row],[Op]]<>"","ENTREGA","") -> ENTREGA | AK9: =(Tabla2[[#This Row],[FECHA ENTREGA]]&Tabla2[[#This Row],[HORA ENTREGA]]) -> 460550,333333333333333 | AL9: =IFERROR(HYPERLINK("https://wa.me/"&Tabla2[[#This Row],[CONTACTO]]&"?text="&Tabla2[[#This Row],[Mensaje]]),"") -> https://wa.me/56967384794?text=Hola!%0AServicio del día 02-02%0A *Cliente:* BAYONA SPA */ Cont: * CMAU7238042*/ HR Entrega: *08:00* /Dirección: * BOULEVAR 1313 BODENOR FLEX CENTER ENEA, PUDAHUEL
A10: =ROW(A9) -> 9 | B10: =IF(J10=J9,B9+1,1) -> 8 | C10: BAYONA SPA | D10: IMPO | E10: 297771 | F10: UETU7315402 | G10: 40 HC | H10: 9000 | I10: FRAGUA | J10: 46055 | K10: 0.45833333 | M10: JUAN BARRAZA | N10: =IFERROR(VLOOKUP(M10,Data!$J$1:$K$58,2,0),"") -> 56944277110 | O10: LFHK-35 | Q10: BOULEVAR 1313 BODENOR FLEX CENTER ENEA, PUDAHUEL | R10: CIS | Y10: ENTREGADO | AA10: 0.52986111 | AC10: 46055 | AD10: =IF(Tabla2[[#This Row],[HORA ENTREGA]]="DIRECTO","On time", IF(AA10<>"",IF(Tabla2[[#This Row],[Fecha Real Entrega]]<Tabla2[[#This Row],[FECHA ENTREGA]],"On time",IF(Tabla2[[#This Row],[Hora Real Entrega]]<=Tabla2[[#This Row],[HORA ENTREGA]]+(15/1440),"On time","Off time")),"Sin llegada")) -> Off time | AE10: =MID(Tabla2[[#This Row],[TIPO]],1,3) -> 40 | AF10: ="Hola!" & "%0A" & "Servicio del día " &TEXT(Tabla2[[#This Row],[FECHA ENTREGA]],"dd-mm") & "%0A" & " *Cliente:* " &Tabla2[[#This Row],[CLIENTE]] & " */ Cont: * "&Tabla2[[#This Row],[CONTENEDOR]] & "*/ HR Entrega: *" & TEXT(Tabla2[[#This Row],[HORA ENTREGA]],"hh:mm") & "* /Dirección: *" & Tabla2[[#This Row],[Dirección Entrega]] -> Hola!%0AServicio del día 02-02%0A *Cliente:* BAYONA SPA */ Cont: * UETU7315402*/ HR Entrega: *11:00* /Dirección: * BOULEVAR 1313 BODENOR FLEX CENTER ENEA, PUDAHUEL | AG10: =IFERROR(HYPERLINK("https://wa.me/"&Tabla2[[#This Row],[CONTACTO]]&"?text="&Tabla2[[#This Row],[Mensaje]],"Enviar mensaje"),"") -> Enviar mensaje | AH10: =CONCATENATE(A10,F10) -> 9UETU7315402 | AI10: =CONCATENATE("ENT-",A10) -> ENT-9 | AJ10: =IF(Tabla2[[#This Row],[Op]]<>"","ENTREGA","") -> ENTREGA | AK10: =(Tabla2[[#This Row],[FECHA ENTREGA]]&Tabla2[[#This Row],[HORA ENTREGA]]) -> 460550,458333333333333 | AL10: =IFERROR(HYPERLINK("https://wa.me/"&Tabla2[[#This Row],[CONTACTO]]&"?text="&Tabla2[[#This Row],[Mensaje]]),"") -> https://wa.me/56944277110?text=Hola!%0AServicio del día 02-02%0A *Cliente:* BAYONA SPA */ Cont: * UETU7315402*/ HR Entrega: *11:00* /Dirección: * BOULEVAR 1313 BODENOR FLEX CENTER ENEA, PUDAHUEL
A11: =ROW(A10) -> 10 | B11: =IF(J11=J10,B10+1,1) -> 9 | C11: CANONTEX | D11: IMPO | E11: 312044 | F11: TCLU6542028 | G11: 20 DV | H11: 17000 | I11: FRAGUA | J11: 46055 | K11: 0.375 | M11: JAIME PINTO YAÑEZ | N11: =IFERROR(VLOOKUP(M11,Data!$J$1:$K$58,2,0),"") -> 56956654384 | O11: LPYG-88 | Q11: Patricia Viñuela N°334, Lampa (BODEGA MPR) | R11: CIS | Y11: ENTREGADO | AA11: 0.375 | AC11: 46055 | AD11: =IF(Tabla2[[#This Row],[HORA ENTREGA]]="DIRECTO","On time", IF(AA11<>"",IF(Tabla2[[#This Row],[Fecha Real Entrega]]<Tabla2[[#This Row],[FECHA ENTREGA]],"On time",IF(Tabla2[[#This Row],[Hora Real Entrega]]<=Tabla2[[#This Row],[HORA ENTREGA]]+(15/1440),"On time","Off time")),"Sin llegada")) -> On time | AE11: =MID(Tabla2[[#This Row],[TIPO]],1,3) -> 20 | AF11: ="Hola!" & "%0A" & "Servicio del día " &TEXT(Tabla2[[#This Row],[FECHA ENTREGA]],"dd-mm") & "%0A" & " *Cliente:* " &Tabla2[[#This Row],[CLIENTE]] & " */ Cont: * "&Tabla2[[#This Row],[CONTENEDOR]] & "*/ HR Entrega: *" & TEXT(Tabla2[[#This Row],[HORA ENTREGA]],"hh:mm") & "* /Dirección: *" & Tabla2[[#This Row],[Dirección Entrega]] -> Hola!%0AServicio del día 02-02%0A *Cliente:* CANONTEX */ Cont: * TCLU6542028*/ HR Entrega: *09:00* /Dirección: *Patricia Viñuela N°334, Lampa (BODEGA MPR) | AG11: =IFERROR(HYPERLINK("https://wa.me/"&Tabla2[[#This Row],[CONTACTO]]&"?text="&Tabla2[[#This Row],[Mensaje]],"Enviar mensaje"),"") -> Enviar mensaje | AH11: =CONCATENATE(A11,F11) -> 10TCLU6542028 | AI11: =CONCATENATE("ENT-",A11) -> ENT-10 | AJ11: =IF(Tabla2[[#This Row],[Op]]<>"","ENTREGA","") -> ENTREGA | AK11: =(Tabla2[[#This Row],[FECHA ENTREGA]]&Tabla2[[#This Row],[HORA ENTREGA]]) -> 460550,375 | AL11: =IFERROR(HYPERLINK("https://wa.me/"&Tabla2[[#This Row],[CONTACTO]]&"?text="&Tabla2[[#This Row],[Mensaje]]),"") -> https://wa.me/56956654384?text=Hola!%0AServicio del día 02-02%0A *Cliente:* CANONTEX */ Cont: * TCLU6542028*/ HR Entrega: *09:00* /Dirección: *Patricia Viñuela N°334, Lampa (BODEGA MPR)
A12: =ROW(A11) -> 11 | B12: =IF(J12=J11,B11+1,1) -> 10 | C12: CANONTEX | D12: IMPO | E12: 311937 | F12: FFAU7478843 | G12: 40 HC | H12: 12000 | I12: FRAGUA | J12: 46055 | K12: 0.375 | M12: JAVIER LOPEZ | N12: =IFERROR(VLOOKUP(M12,Data!$J$1:$K$58,2,0),"") -> 56987557136 | O12: TRKJ-63 | Q12: Patricia Viñuela N°334, Lampa (BODEGA CDC) | R12: CONTOPSA VALP | Y12: ENTREGADO | AA12: 0.38055556 | AC12: 46055 | AD12: =IF(Tabla2[[#This Row],[HORA ENTREGA]]="DIRECTO","On time", IF(AA12<>"",IF(Tabla2[[#This Row],[Fecha Real Entrega]]<Tabla2[[#This Row],[FECHA ENTREGA]],"On time",IF(Tabla2[[#This Row],[Hora Real Entrega]]<=Tabla2[[#This Row],[HORA ENTREGA]]+(15/1440),"On time","Off time")),"Sin llegada")) -> On time | AE12: =MID(Tabla2[[#This Row],[TIPO]],1,3) -> 40 | AF12: ="Hola!" & "%0A" & "Servicio del día " &TEXT(Tabla2[[#This Row],[FECHA ENTREGA]],"dd-mm") & "%0A" & " *Cliente:* " &Tabla2[[#This Row],[CLIENTE]] & " */ Cont: * "&Tabla2[[#This Row],[CONTENEDOR]] & "*/ HR Entrega: *" & TEXT(Tabla2[[#This Row],[HORA ENTREGA]],"hh:mm") & "* /Dirección: *" & Tabla2[[#This Row],[Dirección Entrega]] -> Hola!%0AServicio del día 02-02%0A *Cliente:* CANONTEX */ Cont: * FFAU7478843*/ HR Entrega: *09:00* /Dirección: *Patricia Viñuela N°334, Lampa (BODEGA CDC) | AG12: =IFERROR(HYPERLINK("https://wa.me/"&Tabla2[[#This Row],[CONTACTO]]&"?text="&Tabla2[[#This Row],[Mensaje]],"Enviar mensaje"),"") -> Enviar mensaje | AH12: =CONCATENATE(A12,F12) -> 11FFAU7478843 | AI12: =CONCATENATE("ENT-",A12) -> ENT-11 | AJ12: =IF(Tabla2[[#This Row],[Op]]<>"","ENTREGA","") -> ENTREGA | AK12: =(Tabla2[[#This Row],[FECHA ENTREGA]]&Tabla2[[#This Row],[HORA ENTREGA]]) -> 460550,375 | AL12: =IFERROR(HYPERLINK("https://wa.me/"&Tabla2[[#This Row],[CONTACTO]]&"?text="&Tabla2[[#This Row],[Mensaje]]),"") -> https://wa.me/56987557136?text=Hola!%0AServicio del día 02-02%0A *Cliente:* CANONTEX */ Cont: * FFAU7478843*/ HR Entrega: *09:00* /Dirección: *Patricia Viñuela N°334, Lampa (BODEGA CDC)
A13: =ROW(A12) -> 12 | B13: =IF(J13=J12,B12+1,1) -> 11 | C13: COMERCIAL E INDUSTRIAL PLASTICOS HOFFENS S.A. | D13: IMPO | E13: 296856 | F13: ONEU6023062 | G13: 40 HC | H13: 24000 | I13: 31/01 - 01:10 | J13: 46055 | K13: 0.33333333 | M13: JORGE CARDENAS | N13: =IFERROR(VLOOKUP(M13,Data!$J$1:$K$58,2,0),"") -> 56944540732 | O13: KBKZ-28 | Q13: Hoffens: Camino Lonquén 10.707, Maipú | R13: SITRANS VALP | Y13: ENTREGADO | AA13: 0.32430556 | AC13: 46055 | AD13: =IF(Tabla2[[#This Row],[HORA ENTREGA]]="DIRECTO","On time", IF(AA13<>"",IF(Tabla2[[#This Row],[Fecha Real Entrega]]<Tabla2[[#This Row],[FECHA ENTREGA]],"On time",IF(Tabla2[[#This Row],[Hora Real Entrega]]<=Tabla2[[#This Row],[HORA ENTREGA]]+(15/1440),"On time","Off time")),"Sin llegada")) -> On time | AE13: =MID(Tabla2[[#This Row],[TIPO]],1,3) -> 40 | AF13: ="Hola!" & "%0A" & "Servicio del día " &TEXT(Tabla2[[#This Row],[FECHA ENTREGA]],"dd-mm") & "%0A" & " *Cliente:* " &Tabla2[[#This Row],[CLIENTE]] & " */ Cont: * "&Tabla2[[#This Row],[CONTENEDOR]] & "*/ HR Entrega: *" & TEXT(Tabla2[[#This Row],[HORA ENTREGA]],"hh:mm") & "* /Dirección: *" & Tabla2[[#This Row],[Dirección Entrega]] -> Hola!%0AServicio del día 02-02%0A *Cliente:* COMERCIAL E INDUSTRIAL PLASTICOS HOFFENS S.A. */ Cont: * ONEU6023062*/ HR Entrega: *08:00* /Dirección: *Hoffens: Camino Lonquén 10.707, Maipú | AG13: =IFERROR(HYPERLINK("https://wa.me/"&Tabla2[[#This Row],[CONTACTO]]&"?text="&Tabla2[[#This Row],[Mensaje]],"Enviar mensaje"),"") -> Enviar mensaje | AH13: =CONCATENATE(A13,F13) -> 12ONEU6023062 | AI13: =CONCATENATE("ENT-",A13) -> ENT-12 | AJ13: =IF(Tabla2[[#This Row],[Op]]<>"","ENTREGA","") -> ENTREGA | AK13: =(Tabla2[[#This Row],[FECHA ENTREGA]]&Tabla2[[#This Row],[HORA ENTREGA]]) -> 460550,333333333333333 | AL13: =IFERROR(HYPERLINK("https://wa.me/"&Tabla2[[#This Row],[CONTACTO]]&"?text="&Tabla2[[#This Row],[Mensaje]]),"") -> https://wa.me/56944540732?text=Hola!%0AServicio del día 02-02%0A *Cliente:* COMERCIAL E INDUSTRIAL PLASTICOS HOFFENS S.A. */ Cont: * ONEU6023062*/ HR Entrega: *08:00* /Dirección: *Hoffens: Camino Lonquén 10.707, Maipú
A14: =ROW(A13) -> 13 | B14: =IF(J14=J13,B13+1,1) -> 12 | C14: COMERCIAL PICHARA SPA | D14: IMPO | E14: 141564 | F14: MSNU3058984 | G14: 20 DV | H14: 5000 | I14: 30/01 - 18:00 | J14: 46055 | K14: 0.35416667 | M14: JORGE PACHECO PLAZA | N14: =IFERROR(VLOOKUP(M14,Data!$J$1:$K$58,2,0),"") -> 56966749395 | O14: LPYJ-43 | Q14: Olivo 672, Recoleta | R14: MEDLOG SAI | Y14: ENTREGADO | AA14: 0.3125 | AC14: 46055 | AD14: =IF(Tabla2[[#This Row],[HORA ENTREGA]]="DIRECTO","On time", IF(AA14<>"",IF(Tabla2[[#This Row],[Fecha Real Entrega]]<Tabla2[[#This Row],[FECHA ENTREGA]],"On time",IF(Tabla2[[#This Row],[Hora Real Entrega]]<=Tabla2[[#This Row],[HORA ENTREGA]]+(15/1440),"On time","Off time")),"Sin llegada")) -> On time | AE14: =MID(Tabla2[[#This Row],[TIPO]],1,3) -> 20 | AF14: ="Hola!" & "%0A" & "Servicio del día " &TEXT(Tabla2[[#This Row],[FECHA ENTREGA]],"dd-mm") & "%0A" & " *Cliente:* " &Tabla2[[#This Row],[CLIENTE]] & " */ Cont: * "&Tabla2[[#This Row],[CONTENEDOR]] & "*/ HR Entrega: *" & TEXT(Tabla2[[#This Row],[HORA ENTREGA]],"hh:mm") & "* /Dirección: *" & Tabla2[[#This Row],[Dirección Entrega]] -> Hola!%0AServicio del día 02-02%0A *Cliente:* COMERCIAL PICHARA SPA */ Cont: * MSNU3058984*/ HR Entrega: *08:30* /Dirección: *Olivo 672, Recoleta | AG14: =IFERROR(HYPERLINK("https://wa.me/"&Tabla2[[#This Row],[CONTACTO]]&"?text="&Tabla2[[#This Row],[Mensaje]],"Enviar mensaje"),"") -> Enviar mensaje | AH14: =CONCATENATE(A14,F14) -> 13MSNU3058984 | AI14: =CONCATENATE("ENT-",A14) -> ENT-13 | AJ14: =IF(Tabla2[[#This Row],[Op]]<>"","ENTREGA","") -> ENTREGA | AK14: =(Tabla2[[#This Row],[FECHA ENTREGA]]&Tabla2[[#This Row],[HORA ENTREGA]]) -> 460550,354166666666667 | AL14: =IFERROR(HYPERLINK("https://wa.me/"&Tabla2[[#This Row],[CONTACTO]]&"?text="&Tabla2[[#This Row],[Mensaje]]),"") -> https://wa.me/56966749395?text=Hola!%0AServicio del día 02-02%0A *Cliente:* COMERCIAL PICHARA SPA */ Cont: * MSNU3058984*/ HR Entrega: *08:30* /Dirección: *Olivo 672, Recoleta
A15: =ROW(A14) -> 14 | B15: =IF(J15=J14,B14+1,1) -> 13 | C15: COMERCIAL PICHARA SPA | D15: IMPO | E15: 141546 | F15: MSBU1457587 | G15: 20 DV | H15: 9000 | I15: 30/01 - 18:04 | J15: 46055 | K15: 0.58333333 | M15: DANIEL GOMEZ | N15: =IFERROR(VLOOKUP(M15,Data!$J$1:$K$58,2,0),"") -> 56993389870 | O15: LPYG-89 | Q15: Olivo 740, Recoleta | R15: MEDLOG SAI | Y15: ENTREGADO | AA15: 0.51736111 | AC15: 46055 | AD15: =IF(Tabla2[[#This Row],[HORA ENTREGA]]="DIRECTO","On time", IF(AA15<>"",IF(Tabla2[[#This Row],[Fecha Real Entrega]]<Tabla2[[#This Row],[FECHA ENTREGA]],"On time",IF(Tabla2[[#This Row],[Hora Real Entrega]]<=Tabla2[[#This Row],[HORA ENTREGA]]+(15/1440),"On time","Off time")),"Sin llegada")) -> On time | AE15: =MID(Tabla2[[#This Row],[TIPO]],1,3) -> 20 | AF15: ="Hola!" & "%0A" & "Servicio del día " &TEXT(Tabla2[[#This Row],[FECHA ENTREGA]],"dd-mm") & "%0A" & " *Cliente:* " &Tabla2[[#This Row],[CLIENTE]] & " */ Cont: * "&Tabla2[[#This Row],[CONTENEDOR]] & "*/ HR Entrega: *" & TEXT(Tabla2[[#This Row],[HORA ENTREGA]],"hh:mm") & "* /Dirección: *" & Tabla2[[#This Row],[Dirección Entrega]] -> Hola!%0AServicio del día 02-02%0A *Cliente:* COMERCIAL PICHARA SPA */ Cont: * MSBU1457587*/ HR Entrega: *14:00* /Dirección: *Olivo 740, Recoleta | AG15: =IFERROR(HYPERLINK("https://wa.me/"&Tabla2[[#This Row],[CONTACTO]]&"?text="&Tabla2[[#This Row],[Mensaje]],"Enviar mensaje"),"") -> Enviar mensaje | AH15: =CONCATENATE(A15,F15) -> 14MSBU1457587 | AI15: =CONCATENATE("ENT-",A15) -> ENT-14 | AJ15: =IF(Tabla2[[#This Row],[Op]]<>"","ENTREGA","") -> ENTREGA | AK15: =(Tabla2[[#This Row],[FECHA ENTREGA]]&Tabla2[[#This Row],[HORA ENTREGA]]) -> 460550,583333333333333 | AL15: =IFERROR(HYPERLINK("https://wa.me/"&Tabla2[[#This Row],[CONTACTO]]&"?text="&Tabla2[[#This Row],[Mensaje]]),"") -> https://wa.me/56993389870?text=Hola!%0AServicio del día 02-02%0A *Cliente:* COMERCIAL PICHARA SPA */ Cont: * MSBU1457587*/ HR Entrega: *14:00* /Dirección: *Olivo 740, Recoleta
A16: =ROW(A15) -> 15 | B16: =IF(J16=J15,B15+1,1) -> 14 | C16: COMERCIAL SANDOVAL E HIJOS LTDA | D16: IMPO | E16: 2006659 | F16: HLBU9864873 | G16: 40 HC | H16: 33000 | I16: FRAGUA | J16: 46055 | K16: 0.33333333 | M16: DANNY CARREÑO | N16: =IFERROR(VLOOKUP(M16,Data!$J$1:$K$58,2,0),"") -> 56990025702 | O16: RRVF-72 | Q16: SANTA ISABEL 370; LAMPA | R16: DYC VALP | Y16: ENTREGADO | AA16: 0.31458333 | AC16: 46055 | AD16: =IF(Tabla2[[#This Row],[HORA ENTREGA]]="DIRECTO","On time", IF(AA16<>"",IF(Tabla2[[#This Row],[Fecha Real Entrega]]<Tabla2[[#This Row],[FECHA ENTREGA]],"On time",IF(Tabla2[[#This Row],[Hora Real Entrega]]<=Tabla2[[#This Row],[HORA ENTREGA]]+(15/1440),"On time","Off time")),"Sin llegada")) -> On time | AE16: =MID(Tabla2[[#This Row],[TIPO]],1,3) -> 40 | AF16: ="Hola!" & "%0A" & "Servicio del día " &TEXT(Tabla2[[#This Row],[FECHA ENTREGA]],"dd-mm") & "%0A" & " *Cliente:* " &Tabla2[[#This Row],[CLIENTE]] & " */ Cont: * "&Tabla2[[#This Row],[CONTENEDOR]] & "*/ HR Entrega: *" & TEXT(Tabla2[[#This Row],[HORA ENTREGA]],"hh:mm") & "* /Dirección: *" & Tabla2[[#This Row],[Dirección Entrega]] -> Hola!%0AServicio del día 02-02%0A *Cliente:* COMERCIAL SANDOVAL E HIJOS LTDA */ Cont: * HLBU9864873*/ HR Entrega: *08:00* /Dirección: *SANTA ISABEL 370; LAMPA | AG16: =IFERROR(HYPERLINK("https://wa.me/"&Tabla2[[#This Row],[CONTACTO]]&"?text="&Tabla2[[#This Row],[Mensaje]],"Enviar mensaje"),"") -> Enviar mensaje | AH16: =CONCATENATE(A16,F16) -> 15HLBU9864873 | AI16: =CONCATENATE("ENT-",A16) -> ENT-15 | AJ16: =IF(Tabla2[[#This Row],[Op]]<>"","ENTREGA","") -> ENTREGA | AK16: =(Tabla2[[#This Row],[FECHA ENTREGA]]&Tabla2[[#This Row],[HORA ENTREGA]]) -> 460550,333333333333333 | AL16: =IFERROR(HYPERLINK("https://wa.me/"&Tabla2[[#This Row],[CONTACTO]]&"?text="&Tabla2[[#This Row],[Mensaje]]),"") -> https://wa.me/56990025702?text=Hola!%0AServicio del día 02-02%0A *Cliente:* COMERCIAL SANDOVAL E HIJOS LTDA */ Cont: * HLBU9864873*/ HR Entrega: *08:00* /Dirección: *SANTA ISABEL 370; LAMPA
A17: =ROW(A16) -> 16 | B17: =IF(J17=J16,B16+1,1) -> 15 | C17: FLEX EQUIPOS DE DESCANSO CHILE | D17: IMPO | E17: 298353 | F17: MRSU7190634 | G17: 40 HC | H17: 20000 | I17: 30/01 - 12:09 | J17: 46055 | K17: 0.35416667 | M17: RUBEN YAÑEZ | N17: =IFERROR(VLOOKUP(M17,Data!$J$1:$K$58,2,0),"") -> 56973887539 | O17: RRVF-71 | Q17: MERSAN (José Joaquín Prieto 9001, Lo Espejo. Bodegas: 7-8-9-10-15-16-17-18) | R17: - | Y17: ENTREGADO | AA17: 0.325 | AC17: 46055 | AD17: =IF(Tabla2[[#This Row],[HORA ENTREGA]]="DIRECTO","On time", IF(AA17<>"",IF(Tabla2[[#This Row],[Fecha Real Entrega]]<Tabla2[[#This Row],[FECHA ENTREGA]],"On time",IF(Tabla2[[#This Row],[Hora Real Entrega]]<=Tabla2[[#This Row],[HORA ENTREGA]]+(15/1440),"On time","Off time")),"Sin llegada")) -> On time | AE17: =MID(Tabla2[[#This Row],[TIPO]],1,3) -> 40 | AF17: ="Hola!" & "%0A" & "Servicio del día " &TEXT(Tabla2[[#This Row],[FECHA ENTREGA]],"dd-mm") & "%0A" & " *Cliente:* " &Tabla2[[#This Row],[CLIENTE]] & " */ Cont: * "&Tabla2[[#This Row],[CONTENEDOR]] & "*/ HR Entrega: *" & TEXT(Tabla2[[#This Row],[HORA ENTREGA]],"hh:mm") & "* /Dirección: *" & Tabla2[[#This Row],[Dirección Entrega]] -> Hola!%0AServicio del día 02-02%0A *Cliente:* FLEX EQUIPOS DE DESCANSO CHILE */ Cont: * MRSU7190634*/ HR Entrega: *08:30* /Dirección: *MERSAN (José Joaquín Prieto 9001, Lo Espejo. Bodegas: 7-8-9-10-15-16-17-18) | AG17: =IFERROR(HYPERLINK("https://wa.me/"&Tabla2[[#This Row],[CONTACTO]]&"?text="&Tabla2[[#This Row],[Mensaje]],"Enviar mensaje"),"") -> Enviar mensaje | AH17: =CONCATENATE(A17,F17) -> 16MRSU7190634 | AI17: =CONCATENATE("ENT-",A17) -> ENT-16 | AJ17: =IF(Tabla2[[#This Row],[Op]]<>"","ENTREGA","") -> ENTREGA | AK17: =(Tabla2[[#This Row],[FECHA ENTREGA]]&Tabla2[[#This Row],[HORA ENTREGA]]) -> 460550,354166666666667 | AL17: =IFERROR(HYPERLINK("https://wa.me/"&Tabla2[[#This Row],[CONTACTO]]&"?text="&Tabla2[[#This Row],[Mensaje]]),"") -> https://wa.me/56973887539?text=Hola!%0AServicio del día 02-02%0A *Cliente:* FLEX EQUIPOS DE DESCANSO CHILE */ Cont: * MRSU7190634*/ HR Entrega: *08:30* /Dirección: *MERSAN (José Joaquín Prieto 9001, Lo Espejo. Bodegas: 7-8-9-10-15-16-17-18)
A18: =ROW(A17) -> 17 | B18: =IF(J18=J17,B17+1,1) -> 16 | C18: GREENEX SPA | D18: EXPO | E18: Booking: SNG0492506 | F18: AMCU9392271 | G18: 40 RF | H18: - | I18: EXPORTACION | J18: 46055 | K18: 0.375 | M18: GABRIEL SALAS | N18: =IFERROR(VLOOKUP(M18,Data!$J$1:$K$58,2,0),"") -> 56999270871 | O18: RFZW-98 | Q18: CONSOLIDADO: PLANTA GREENEX - AV.O'HIGGINS 740, CODEGUA / EMBARQUE: STI | R18: RETIRO VACIO: AGUNSA SAI | AA18: 0.37152778 | AC18: 46055 | AD18: =IF(Tabla2[[#This Row],[HORA ENTREGA]]="DIRECTO","On time", IF(AA18<>"",IF(Tabla2[[#This Row],[Fecha Real Entrega]]<Tabla2[[#This Row],[FECHA ENTREGA]],"On time",IF(Tabla2[[#This Row],[Hora Real Entrega]]<=Tabla2[[#This Row],[HORA ENTREGA]]+(15/1440),"On time","Off time")),"Sin llegada")) -> On time | AE18: =MID(Tabla2[[#This Row],[TIPO]],1,3) -> 40 | AF18: ="Hola!" & "%0A" & "Servicio del día " &TEXT(Tabla2[[#This Row],[FECHA ENTREGA]],"dd-mm") & "%0A" & " *Cliente:* " &Tabla2[[#This Row],[CLIENTE]] & " */ Cont: * "&Tabla2[[#This Row],[CONTENEDOR]] & "*/ HR Entrega: *" & TEXT(Tabla2[[#This Row],[HORA ENTREGA]],"hh:mm") & "* /Dirección: *" & Tabla2[[#This Row],[Dirección Entrega]] -> Hola!%0AServicio del día 02-02%0A *Cliente:* GREENEX SPA */ Cont: * AMCU9392271*/ HR Entrega: *09:00* /Dirección: *CONSOLIDADO: PLANTA GREENEX - AV.O'HIGGINS 740, CODEGUA / EMBARQUE: STI | AG18: =IFERROR(HYPERLINK("https://wa.me/"&Tabla2[[#This Row],[CONTACTO]]&"?text="&Tabla2[[#This Row],[Mensaje]],"Enviar mensaje"),"") -> Enviar mensaje | AH18: =CONCATENATE(A18,F18) -> 17AMCU9392271 | AI18: =CONCATENATE("ENT-",A18) -> ENT-17 | AJ18: =IF(Tabla2[[#This Row],[Op]]<>"","ENTREGA","") -> ENTREGA | AK18: =(Tabla2[[#This Row],[FECHA ENTREGA]]&Tabla2[[#This Row],[HORA ENTREGA]]) -> 460550,375 | AL18: =IFERROR(HYPERLINK("https://wa.me/"&Tabla2[[#This Row],[CONTACTO]]&"?text="&Tabla2[[#This Row],[Mensaje]]),"") -> https://wa.me/56999270871?text=Hola!%0AServicio del día 02-02%0A *Cliente:* GREENEX SPA */ Cont: * AMCU9392271*/ HR Entrega: *09:00* /Dirección: *CONSOLIDADO: PLANTA GREENEX - AV.O'HIGGINS 740, CODEGUA / EMBARQUE: STI
A19: =ROW(A18) -> 18 | B19: =IF(J19=J18,B18+1,1) -> 17 | C19: HORTIFRUT | D19: EXPO | E19: booking: 12089088 | F19: HLBU9428740 | G19: 40 RF | H19: - | I19: EXPORTACION | J19: 46055 | K19: 0.375 | M19: ANTONIO ALCARAZ | N19: =IFERROR(VLOOKUP(M19,Data!$J$1:$K$58,2,0),"") -> 56953801607 | O19: PFVJ-33 | Q19: CONSOLIDADO: VIRQUENCO / EMBARQUE: SAI | R19: RETIRO VACIO: DYC SAI | AA19: 0.96875 | AC19: 46054 | AD19: =IF(Tabla2[[#This Row],[HORA ENTREGA]]="DIRECTO","On time", IF(AA19<>"",IF(Tabla2[[#This Row],[Fecha Real Entrega]]<Tabla2[[#This Row],[FECHA ENTREGA]],"On time",IF(Tabla2[[#This Row],[Hora Real Entrega]]<=Tabla2[[#This Row],[HORA ENTREGA]]+(15/1440),"On time","Off time")),"Sin llegada")) -> On time | AE19: =MID(Tabla2[[#This Row],[TIPO]],1,3) -> 40 | AF19: ="Hola!" & "%0A" & "Servicio del día " &TEXT(Tabla2[[#This Row],[FECHA ENTREGA]],"dd-mm") & "%0A" & " *Cliente:* " &Tabla2[[#This Row],[CLIENTE]] & " */ Cont: * "&Tabla2[[#This Row],[CONTENEDOR]] & "*/ HR Entrega: *" & TEXT(Tabla2[[#This Row],[HORA ENTREGA]],"hh:mm") & "* /Dirección: *" & Tabla2[[#This Row],[Dirección Entrega]] -> Hola!%0AServicio del día 02-02%0A *Cliente:* HORTIFRUT */ Cont: * HLBU9428740*/ HR Entrega: *09:00* /Dirección: *CONSOLIDADO: VIRQUENCO / EMBARQUE: SAI | AG19: =IFERROR(HYPERLINK("https://wa.me/"&Tabla2[[#This Row],[CONTACTO]]&"?text="&Tabla2[[#This Row],[Mensaje]],"Enviar mensaje"),"") -> Enviar mensaje | AH19: =CONCATENATE(A19,F19) -> 18HLBU9428740 | AI19: =CONCATENATE("ENT-",A19) -> ENT-18 | AJ19: =IF(Tabla2[[#This Row],[Op]]<>"","ENTREGA","") -> ENTREGA | AK19: =(Tabla2[[#This Row],[FECHA ENTREGA]]&Tabla2[[#This Row],[HORA ENTREGA]]) -> 460550,375 | AL19: =IFERROR(HYPERLINK("https://wa.me/"&Tabla2[[#This Row],[CONTACTO]]&"?text="&Tabla2[[#This Row],[Mensaje]]),"") -> https://wa.me/56953801607?text=Hola!%0AServicio del día 02-02%0A *Cliente:* HORTIFRUT */ Cont: * HLBU9428740*/ HR Entrega: *09:00* /Dirección: *CONSOLIDADO: VIRQUENCO / EMBARQUE: SAI
A20: =ROW(A19) -> 19 | B20: =IF(J20=J19,B19+1,1) -> 18 | C20: HORTIFRUT | D20: EXPO | E20: booking: SRC260001015 | F20: FDDU2543588 | G20: 40 RF | H20: - | I20: EXPORTACION | J20: 46055 | K20: 0.41666667 | M20: JUAN ESPINOZA | N20: =IFERROR(VLOOKUP(M20,Data!$J$1:$K$58,2,0),"") -> 56965312953 | O20: LGGR-15 | Q20: CONSOLIDADO: CARRERA 695, GORBEA - PLANTA HORTIFRUT GORBEA / EMBARQUE: VALP | R20: RETIRO VACIO: AGUNSA VALP | AA20: 0.010416667 | AC20: 46055 | AD20: =IF(Tabla2[[#This Row],[HORA ENTREGA]]="DIRECTO","On time", IF(AA20<>"",IF(Tabla2[[#This Row],[Fecha Real Entrega]]<Tabla2[[#This Row],[FECHA ENTREGA]],"On time",IF(Tabla2[[#This Row],[Hora Real Entrega]]<=Tabla2[[#This Row],[HORA ENTREGA]]+(15/1440),"On time","Off time")),"Sin llegada")) -> On time | AE20: =MID(Tabla2[[#This Row],[TIPO]],1,3) -> 40 | AF20: ="Hola!" & "%0A" & "Servicio del día " &TEXT(Tabla2[[#This Row],[FECHA ENTREGA]],"dd-mm") & "%0A" & " *Cliente:* " &Tabla2[[#This Row],[CLIENTE]] & " */ Cont: * "&Tabla2[[#This Row],[CONTENEDOR]] & "*/ HR Entrega: *" & TEXT(Tabla2[[#This Row],[HORA ENTREGA]],"hh:mm") & "* /Dirección: *" & Tabla2[[#This Row],[Dirección Entrega]] -> Hola!%0AServicio del día 02-02%0A *Cliente:* HORTIFRUT */ Cont: * FDDU2543588*/ HR Entrega: *10:00* /Dirección: *CONSOLIDADO: CARRERA 695, GORBEA - PLANTA HORTIFRUT GORBEA / EMBARQUE: VALP | AG20: =IFERROR(HYPERLINK("https://wa.me/"&Tabla2[[#This Row],[CONTACTO]]&"?text="&Tabla2[[#This Row],[Mensaje]],"Enviar mensaje"),"") -> Enviar mensaje | AH20: =CONCATENATE(A20,F20) -> 19FDDU2543588 | AI20: =CONCATENATE("ENT-",A20) -> ENT-19 | AJ20: =IF(Tabla2[[#This Row],[Op]]<>"","ENTREGA","") -> ENTREGA | AK20: =(Tabla2[[#This Row],[FECHA ENTREGA]]&Tabla2[[#This Row],[HORA ENTREGA]]) -> 460550,416666666666667 | AL20: =IFERROR(HYPERLINK("https://wa.me/"&Tabla2[[#This Row],[CONTACTO]]&"?text="&Tabla2[[#This Row],[Mensaje]]),"") -> https://wa.me/56965312953?text=Hola!%0AServicio del día 02-02%0A *Cliente:* HORTIFRUT */ Cont: * FDDU2543588*/ HR Entrega: *10:00* /Dirección: *CONSOLIDADO: CARRERA 695, GORBEA - PLANTA HORTIFRUT GORBEA / EMBARQUE: VALP
A21: =ROW(A20) -> 20 | B21: =IF(J21=J20,B20+1,1) -> 19 | C21: HORTIFRUT | D21: EXPO | E21: booking: 12089088 | F21: HLBU9181199 | G21: 40 RF | H21: - | I21: EXPORTACION | J21: 46055 | K21: 0.4375 | M21: JOSE ROJAS | N21: =IFERROR(VLOOKUP(M21,Data!$J$1:$K$58,2,0),"") -> 56940144795 | O21: TSYB-23 | Q21: CONSOLIDADO: VIRQUENCO / EMBARQUE: SAI | R21: RETIRO VACIO: DYC SAI | AA21: 0.97222222 | AC21: 46054 | AD21: =IF(Tabla2[[#This Row],[HORA ENTREGA]]="DIRECTO","On time", IF(AA21<>"",IF(Tabla2[[#This Row],[Fecha Real Entrega]]<Tabla2[[#This Row],[FECHA ENTREGA]],"On time",IF(Tabla2[[#This Row],[Hora Real Entrega]]<=Tabla2[[#This Row],[HORA ENTREGA]]+(15/1440),"On time","Off time")),"Sin llegada")) -> On time | AE21: =MID(Tabla2[[#This Row],[TIPO]],1,3) -> 40 | AF21: ="Hola!" & "%0A" & "Servicio del día " &TEXT(Tabla2[[#This Row],[FECHA ENTREGA]],"dd-mm") & "%0A" & " *Cliente:* " &Tabla2[[#This Row],[CLIENTE]] & " */ Cont: * "&Tabla2[[#This Row],[CONTENEDOR]] & "*/ HR Entrega: *" & TEXT(Tabla2[[#This Row],[HORA ENTREGA]],"hh:mm") & "* /Dirección: *" & Tabla2[[#This Row],[Dirección Entrega]] -> Hola!%0AServicio del día 02-02%0A *Cliente:* HORTIFRUT */ Cont: * HLBU9181199*/ HR Entrega: *10:30* /Dirección: *CONSOLIDADO: VIRQUENCO / EMBARQUE: SAI | AG21: =IFERROR(HYPERLINK("https://wa.me/"&Tabla2[[#This Row],[CONTACTO]]&"?text="&Tabla2[[#This Row],[Mensaje]],"Enviar mensaje"),"") -> Enviar mensaje | AH21: =CONCATENATE(A21,F21) -> 20HLBU9181199 | AI21: =CONCATENATE("ENT-",A21) -> ENT-20 | AJ21: =IF(Tabla2[[#This Row],[Op]]<>"","ENTREGA","") -> ENTREGA | AK21: =(Tabla2[[#This Row],[FECHA ENTREGA]]&Tabla2[[#This Row],[HORA ENTREGA]]) -> 460550,4375 | AL21: =IFERROR(HYPERLINK("https://wa.me/"&Tabla2[[#This Row],[CONTACTO]]&"?text="&Tabla2[[#This Row],[Mensaje]]),"") -> https://wa.me/56940144795?text=Hola!%0AServicio del día 02-02%0A *Cliente:* HORTIFRUT */ Cont: * HLBU9181199*/ HR Entrega: *10:30* /Dirección: *CONSOLIDADO: VIRQUENCO / EMBARQUE: SAI
A22: =ROW(A21) -> 21 | B22: =IF(J22=J21,B21+1,1) -> 20 | C22: HORTIFRUT | D22: EXPO | E22: booking: 12089088 | F22: HLBU9265140 | G22: 40 RF | H22: - | I22: EXPORTACION | J22: 46055 | K22: 0.5 | M22: JULIO CATALAN | N22: =IFERROR(VLOOKUP(M22,Data!$J$1:$K$58,2,0),"") -> 56935532735 | O22: TSYB-22 | Q22: CONSOLIDADO: VIRQUENCO / EMBARQUE: SAI | R22: RETIRO VACIO: DYC SAI | AA22: 0.97222222 | AC22: 46054 | AD22: =IF(Tabla2[[#This Row],[HORA ENTREGA]]="DIRECTO","On time", IF(AA22<>"",IF(Tabla2[[#This Row],[Fecha Real Entrega]]<Tabla2[[#This Row],[FECHA ENTREGA]],"On time",IF(Tabla2[[#This Row],[Hora Real Entrega]]<=Tabla2[[#This Row],[HORA ENTREGA]]+(15/1440),"On time","Off time")),"Sin llegada")) -> On time | AE22: =MID(Tabla2[[#This Row],[TIPO]],1,3) -> 40 | AF22: ="Hola!" & "%0A" & "Servicio del día " &TEXT(Tabla2[[#This Row],[FECHA ENTREGA]],"dd-mm") & "%0A" & " *Cliente:* " &Tabla2[[#This Row],[CLIENTE]] & " */ Cont: * "&Tabla2[[#This Row],[CONTENEDOR]] & "*/ HR Entrega: *" & TEXT(Tabla2[[#This Row],[HORA ENTREGA]],"hh:mm") & "* /Dirección: *" & Tabla2[[#This Row],[Dirección Entrega]] -> Hola!%0AServicio del día 02-02%0A *Cliente:* HORTIFRUT */ Cont: * HLBU9265140*/ HR Entrega: *12:00* /Dirección: *CONSOLIDADO: VIRQUENCO / EMBARQUE: SAI | AG22: =IFERROR(HYPERLINK("https://wa.me/"&Tabla2[[#This Row],[CONTACTO]]&"?text="&Tabla2[[#This Row],[Mensaje]],"Enviar mensaje"),"") -> Enviar mensaje | AH22: =CONCATENATE(A22,F22) -> 21HLBU9265140 | AI22: =CONCATENATE("ENT-",A22) -> ENT-21 | AJ22: =IF(Tabla2[[#This Row],[Op]]<>"","ENTREGA","") -> ENTREGA | AK22: =(Tabla2[[#This Row],[FECHA ENTREGA]]&Tabla2[[#This Row],[HORA ENTREGA]]) -> 460550,5 | AL22: =IFERROR(HYPERLINK("https://wa.me/"&Tabla2[[#This Row],[CONTACTO]]&"?text="&Tabla2[[#This Row],[Mensaje]]),"") -> https://wa.me/56935532735?text=Hola!%0AServicio del día 02-02%0A *Cliente:* HORTIFRUT */ Cont: * HLBU9265140*/ HR Entrega: *12:00* /Dirección: *CONSOLIDADO: VIRQUENCO / EMBARQUE: SAI
A23: =ROW(A22) -> 22 | B23: =IF(J23=J22,B22+1,1) -> 21 | C23: IMPORTADORA MIDEA CARRIER CHILE LTDA | D23: IMPO | E23: 2590530 | F23: TIIU6476679 | G23: 40 HC | H23: 10000 | I23: FRAGUA | J23: 46055 | K23: 0.375 | M23: JOSE SALAZAR | N23: =IFERROR(VLOOKUP(M23,Data!$J$1:$K$58,2,0),"") -> 56973887427 | O23: TRKJ-65 | Q23: BOD. MIEA AGURTO - PUERTO MADERO 9710, BOD. E13; PUDAHUEL | R23: CIS | Y23: ENTREGADO | AA23: 0.36111111 | AC23: 46055 | AD23: =IF(Tabla2[[#This Row],[HORA ENTREGA]]="DIRECTO","On time", IF(AA23<>"",IF(Tabla2[[#This Row],[Fecha Real Entrega]]<Tabla2[[#This Row],[FECHA ENTREGA]],"On time",IF(Tabla2[[#This Row],[Hora Real Entrega]]<=Tabla2[[#This Row],[HORA ENTREGA]]+(15/1440),"On time","Off time")),"Sin llegada")) -> On time | AE23: =MID(Tabla2[[#This Row],[TIPO]],1,3) -> 40 | AF23: ="Hola!" & "%0A" & "Servicio del día " &TEXT(Tabla2[[#This Row],[FECHA ENTREGA]],"dd-mm") & "%0A" & " *Cliente:* " &Tabla2[[#This Row],[CLIENTE]] & " */ Cont: * "&Tabla2[[#This Row],[CONTENEDOR]] & "*/ HR Entrega: *" & TEXT(Tabla2[[#This Row],[HORA ENTREGA]],"hh:mm") & "* /Dirección: *" & Tabla2[[#This Row],[Dirección Entrega]] -> Hola!%0AServicio del día 02-02%0A *Cliente:* IMPORTADORA MIDEA CARRIER CHILE LTDA */ Cont: * TIIU6476679*/ HR Entrega: *09:00* /Dirección: *BOD. MIEA AGURTO - PUERTO MADERO 9710, BOD. E13; PUDAHUEL | AG23: =IFERROR(HYPERLINK("https://wa.me/"&Tabla2[[#This Row],[CONTACTO]]&"?text="&Tabla2[[#This Row],[Mensaje]],"Enviar mensaje"),"") -> Enviar mensaje | AH23: =CONCATENATE(A23,F23) -> 22TIIU6476679 | AI23: =CONCATENATE("ENT-",A23) -> ENT-22 | AJ23: =IF(Tabla2[[#This Row],[Op]]<>"","ENTREGA","") -> ENTREGA | AK23: =(Tabla2[[#This Row],[FECHA ENTREGA]]&Tabla2[[#This Row],[HORA ENTREGA]]) -> 460550,375 | AL23: =IFERROR(HYPERLINK("https://wa.me/"&Tabla2[[#This Row],[CONTACTO]]&"?text="&Tabla2[[#This Row],[Mensaje]]),"") -> https://wa.me/56973887427?text=Hola!%0AServicio del día 02-02%0A *Cliente:* IMPORTADORA MIDEA CARRIER CHILE LTDA */ Cont: * TIIU6476679*/ HR Entrega: *09:00* /Dirección: *BOD. MIEA AGURTO - PUERTO MADERO 9710, BOD. E13; PUDAHUEL
A24: =ROW(A23) -> 23 | B24: =IF(J24=J23,B23+1,1) -> 22 | C24: IMPORTADORA MIDEA CARRIER CHILE LTDA | D24: IMPO | E24: 2593555 | F24: TCLU1522380 | G24: 40 HC | H24: 10000 | I24: FRAGUA | J24: 46055 | K24: 0.41666667 | M24: GERLINDHER BERNUY | N24: =IFERROR(VLOOKUP(M24,Data!$J$1:$K$58,2,0),"") -> 56926181825 | O24: RLGL-23 | Q24: BOD. MIEA AGURTO - PUERTO MADERO 9710, BOD. E13; PUDAHUEL | R24: CIS | Y24: ENTREGADO | AA24: 0.38958333 | AC24: 46055 | AD24: =IF(Tabla2[[#This Row],[HORA ENTREGA]]="DIRECTO","On time", IF(AA24<>"",IF(Tabla2[[#This Row],[Fecha Real Entrega]]<Tabla2[[#This Row],[FECHA ENTREGA]],"On time",IF(Tabla2[[#This Row],[Hora Real Entrega]]<=Tabla2[[#This Row],[HORA ENTREGA]]+(15/1440),"On time","Off time")),"Sin llegada")) -> On time | AE24: =MID(Tabla2[[#This Row],[TIPO]],1,3) -> 40 | AF24: ="Hola!" & "%0A" & "Servicio del día " &TEXT(Tabla2[[#This Row],[FECHA ENTREGA]],"dd-mm") & "%0A" & " *Cliente:* " &Tabla2[[#This Row],[CLIENTE]] & " */ Cont: * "&Tabla2[[#This Row],[CONTENEDOR]] & "*/ HR Entrega: *" & TEXT(Tabla2[[#This Row],[HORA ENTREGA]],"hh:mm") & "* /Dirección: *" & Tabla2[[#This Row],[Dirección Entrega]] -> Hola!%0AServicio del día 02-02%0A *Cliente:* IMPORTADORA MIDEA CARRIER CHILE LTDA */ Cont: * TCLU1522380*/ HR Entrega: *10:00* /Dirección: *BOD. MIEA AGURTO - PUERTO MADERO 9710, BOD. E13; PUDAHUEL | AG24: =IFERROR(HYPERLINK("https://wa.me/"&Tabla2[[#This Row],[CONTACTO]]&"?text="&Tabla2[[#This Row],[Mensaje]],"Enviar mensaje"),"") -> Enviar mensaje | AH24: =CONCATENATE(A24,F24) -> 23TCLU1522380 | AI24: =CONCATENATE("ENT-",A24) -> ENT-23 | AJ24: =IF(Tabla2[[#This Row],[Op]]<>"","ENTREGA","") -> ENTREGA | AK24: =(Tabla2[[#This Row],[FECHA ENTREGA]]&Tabla2[[#This Row],[HORA ENTREGA]]) -> 460550,416666666666667 | AL24: =IFERROR(HYPERLINK("https://wa.me/"&Tabla2[[#This Row],[CONTACTO]]&"?text="&Tabla2[[#This Row],[Mensaje]]),"") -> https://wa.me/56926181825?text=Hola!%0AServicio del día 02-02%0A *Cliente:* IMPORTADORA MIDEA CARRIER CHILE LTDA */ Cont: * TCLU1522380*/ HR Entrega: *10:00* /Dirección: *BOD. MIEA AGURTO - PUERTO MADERO 9710, BOD. E13; PUDAHUEL
A25: =ROW(A24) -> 24 | B25: =IF(J25=J24,B24+1,1) -> 23 | C25: IMPORTADORA MIDEA CARRIER CHILE LTDA | D25: IMPO | E25: 2593555 | F25: GAOU6814495 | G25: 40 HC | H25: 10000 | I25: FRAGUA | J25: 46055 | K25: 0.41666667 | M25: SEBASTIAN CUETO | N25: =IFERROR(VLOOKUP(M25,Data!$J$1:$K$58,2,0),"") -> 56931745801 | O25: THYG-62 | Q25: BOD. MIEA AGURTO - PUERTO MADERO 9710, BOD. E13; PUDAHUEL | R25: CIS | Y25: ENTREGADO | AA25: 0.33333333 | AC25: 46055 | AD25: =IF(Tabla2[[#This Row],[HORA ENTREGA]]="DIRECTO","On time", IF(AA25<>"",IF(Tabla2[[#This Row],[Fecha Real Entrega]]<Tabla2[[#This Row],[FECHA ENTREGA]],"On time",IF(Tabla2[[#This Row],[Hora Real Entrega]]<=Tabla2[[#This Row],[HORA ENTREGA]]+(15/1440),"On time","Off time")),"Sin llegada")) -> On time | AE25: =MID(Tabla2[[#This Row],[TIPO]],1,3) -> 40 | AF25: ="Hola!" & "%0A" & "Servicio del día " &TEXT(Tabla2[[#This Row],[FECHA ENTREGA]],"dd-mm") & "%0A" & " *Cliente:* " &Tabla2[[#This Row],[CLIENTE]] & " */ Cont: * "&Tabla2[[#This Row],[CONTENEDOR]] & "*/ HR Entrega: *" & TEXT(Tabla2[[#This Row],[HORA ENTREGA]],"hh:mm") & "* /Dirección: *" & Tabla2[[#This Row],[Dirección Entrega]] -> Hola!%0AServicio del día 02-02%0A *Cliente:* IMPORTADORA MIDEA CARRIER CHILE LTDA */ Cont: * GAOU6814495*/ HR Entrega: *10:00* /Dirección: *BOD. MIEA AGURTO - PUERTO MADERO 9710, BOD. E13; PUDAHUEL | AG25: =IFERROR(HYPERLINK("https://wa.me/"&Tabla2[[#This Row],[CONTACTO]]&"?text="&Tabla2[[#This Row],[Mensaje]],"Enviar mensaje"),"") -> Enviar mensaje | AH25: =CONCATENATE(A25,F25) -> 24GAOU6814495 | AI25: =CONCATENATE("ENT-",A25) -> ENT-24 | AJ25: =IF(Tabla2[[#This Row],[Op]]<>"","ENTREGA","") -> ENTREGA | AK25: =(Tabla2[[#This Row],[FECHA ENTREGA]]&Tabla2[[#This Row],[HORA ENTREGA]]) -> 460550,416666666666667 | AL25: =IFERROR(HYPERLINK("https://wa.me/"&Tabla2[[#This Row],[CONTACTO]]&"?text="&Tabla2[[#This Row],[Mensaje]]),"") -> https://wa.me/56931745801?text=Hola!%0AServicio del día 02-02%0A *Cliente:* IMPORTADORA MIDEA CARRIER CHILE LTDA */ Cont: * GAOU6814495*/ HR Entrega: *10:00* /Dirección: *BOD. MIEA AGURTO - PUERTO MADERO 9710, BOD. E13; PUDAHUEL
A26: =ROW(A25) -> 25 | B26: =IF(J26=J25,B25+1,1) -> 24 | C26: IMPORTADORA MIDEA CARRIER CHILE LTDA | D26: IMPO | E26: 2593555 | F26: TLLU4316890 | G26: 40 HC | H26: 10000 | I26: FRAGUA | J26: 46055 | K26: 0.41666667 | M26: CHARLES DIAZ | N26: =IFERROR(VLOOKUP(M26,Data!$J$1:$K$58,2,0),"") -> 56966749408 | O26: RVFP-35 | Q26: BOD. MIEA AGURTO - PUERTO MADERO 9710, BOD. E13; PUDAHUEL | R26: CIS | Y26: ENTREGADO | AA26: 0.62916667 | AC26: 46055 | AD26: =IF(Tabla2[[#This Row],[HORA ENTREGA]]="DIRECTO","On time", IF(AA26<>"",IF(Tabla2[[#This Row],[Fecha Real Entrega]]<Tabla2[[#This Row],[FECHA ENTREGA]],"On time",IF(Tabla2[[#This Row],[Hora Real Entrega]]<=Tabla2[[#This Row],[HORA ENTREGA]]+(15/1440),"On time","Off time")),"Sin llegada")) -> Off time | AE26: =MID(Tabla2[[#This Row],[TIPO]],1,3) -> 40 | AF26: ="Hola!" & "%0A" & "Servicio del día " &TEXT(Tabla2[[#This Row],[FECHA ENTREGA]],"dd-mm") & "%0A" & " *Cliente:* " &Tabla2[[#This Row],[CLIENTE]] & " */ Cont: * "&Tabla2[[#This Row],[CONTENEDOR]] & "*/ HR Entrega: *" & TEXT(Tabla2[[#This Row],[HORA ENTREGA]],"hh:mm") & "* /Dirección: *" & Tabla2[[#This Row],[Dirección Entrega]] -> Hola!%0AServicio del día 02-02%0A *Cliente:* IMPORTADORA MIDEA CARRIER CHILE LTDA */ Cont: * TLLU4316890*/ HR Entrega: *10:00* /Dirección: *BOD. MIEA AGURTO - PUERTO MADERO 9710, BOD. E13; PUDAHUEL | AG26: =IFERROR(HYPERLINK("https://wa.me/"&Tabla2[[#This Row],[CONTACTO]]&"?text="&Tabla2[[#This Row],[Mensaje]],"Enviar mensaje"),"") -> Enviar mensaje | AH26: =CONCATENATE(A26,F26) -> 25TLLU4316890 | AI26: =CONCATENATE("ENT-",A26) -> ENT-25 | AJ26: =IF(Tabla2[[#This Row],[Op]]<>"","ENTREGA","") -> ENTREGA | AK26: =(Tabla2[[#This Row],[FECHA ENTREGA]]&Tabla2[[#This Row],[HORA ENTREGA]]) -> 460550,416666666666667 | AL26: =IFERROR(HYPERLINK("https://wa.me/"&Tabla2[[#This Row],[CONTACTO]]&"?text="&Tabla2[[#This Row],[Mensaje]]),"") -> https://wa.me/56966749408?text=Hola!%0AServicio del día 02-02%0A *Cliente:* IMPORTADORA MIDEA CARRIER CHILE LTDA */ Cont: * TLLU4316890*/ HR Entrega: *10:00* /Dirección: *BOD. MIEA AGURTO - PUERTO MADERO 9710, BOD. E13; PUDAHUEL
A27: =ROW(A26) -> 26 | B27: =IF(J27=J26,B26+1,1) -> 25 | C27: IMPORTADORA MIDEA CARRIER CHILE LTDA | D27: IMPO | E27: 2593555 | F27: TRHU7873593 | G27: 40 HC | H27: 10000 | I27: FRAGUA | J27: 46055 | K27: 0.41666667 | M27: JUAN SANHUEZA | N27: =IFERROR(VLOOKUP(M27,Data!$J$1:$K$58,2,0),"") -> 56967398822 | O27: LGGR-16 | Q27: BOD. MIEA AGURTO - PUERTO MADERO 9710, BOD. E13; PUDAHUEL | R27: CIS | Y27: ENTREGADO | AA27: 0.54513889 | AC27: 46055 | AD27: =IF(Tabla2[[#This Row],[HORA ENTREGA]]="DIRECTO","On time", IF(AA27<>"",IF(Tabla2[[#This Row],[Fecha Real Entrega]]<Tabla2[[#This Row],[FECHA ENTREGA]],"On time",IF(Tabla2[[#This Row],[Hora Real Entrega]]<=Tabla2[[#This Row],[HORA ENTREGA]]+(15/1440),"On time","Off time")),"Sin llegada")) -> Off time | AE27: =MID(Tabla2[[#This Row],[TIPO]],1,3) -> 40 | AF27: ="Hola!" & "%0A" & "Servicio del día " &TEXT(Tabla2[[#This Row],[FECHA ENTREGA]],"dd-mm") & "%0A" & " *Cliente:* " &Tabla2[[#This Row],[CLIENTE]] & " */ Cont: * "&Tabla2[[#This Row],[CONTENEDOR]] & "*/ HR Entrega: *" & TEXT(Tabla2[[#This Row],[HORA ENTREGA]],"hh:mm") & "* /Dirección: *" & Tabla2[[#This Row],[Dirección Entrega]] -> Hola!%0AServicio del día 02-02%0A *Cliente:* IMPORTADORA MIDEA CARRIER CHILE LTDA */ Cont: * TRHU7873593*/ HR Entrega: *10:00* /Dirección: *BOD. MIEA AGURTO - PUERTO MADERO 9710, BOD. E13; PUDAHUEL | AG27: =IFERROR(HYPERLINK("https://wa.me/"&Tabla2[[#This Row],[CONTACTO]]&"?text="&Tabla2[[#This Row],[Mensaje]],"Enviar mensaje"),"") -> Enviar mensaje | AH27: =CONCATENATE(A27,F27) -> 26TRHU7873593 | AI27: =CONCATENATE("ENT-",A27) -> ENT-26 | AJ27: =IF(Tabla2[[#This Row],[Op]]<>"","ENTREGA","") -> ENTREGA | AK27: =(Tabla2[[#This Row],[FECHA ENTREGA]]&Tabla2[[#This Row],[HORA ENTREGA]]) -> 460550,416666666666667 | AL27: =IFERROR(HYPERLINK("https://wa.me/"&Tabla2[[#This Row],[CONTACTO]]&"?text="&Tabla2[[#This Row],[Mensaje]]),"") -> https://wa.me/56967398822?text=Hola!%0AServicio del día 02-02%0A *Cliente:* IMPORTADORA MIDEA CARRIER CHILE LTDA */ Cont: * TRHU7873593*/ HR Entrega: *10:00* /Dirección: *BOD. MIEA AGURTO - PUERTO MADERO 9710, BOD. E13; PUDAHUEL
A28: =ROW(A27) -> 27 | B28: =IF(J28=J27,B27+1,1) -> 26 | C28: IMPORTADORA Y COMERCIALIZADORA BZ SPA | D28: IMPO | E28: 871363 | F28: MSMU5843771 | G28: 40 HC | H28: 16000 | I28: FRAGUA | J28: 46055 | K28: 0.45833333 | M28: JORGE CARDENAS | N28: =IFERROR(VLOOKUP(M28,Data!$J$1:$K$58,2,0),"") -> 56944540732 | O28: KBKZ-28 | Q28: PuertoMadero 9710, Bodega X36. Pudahuel | R28: MEDLOG STGO | Y28: ENTREGADO | AA28: 0.51388889 | AC28: 46055 | AD28: =IF(Tabla2[[#This Row],[HORA ENTREGA]]="DIRECTO","On time", IF(AA28<>"",IF(Tabla2[[#This Row],[Fecha Real Entrega]]<Tabla2[[#This Row],[FECHA ENTREGA]],"On time",IF(Tabla2[[#This Row],[Hora Real Entrega]]<=Tabla2[[#This Row],[HORA ENTREGA]]+(15/1440),"On time","Off time")),"Sin llegada")) -> Off time | AE28: =MID(Tabla2[[#This Row],[TIPO]],1,3) -> 40 | AF28: ="Hola!" & "%0A" & "Servicio del día " &TEXT(Tabla2[[#This Row],[FECHA ENTREGA]],"dd-mm") & "%0A" & " *Cliente:* " &Tabla2[[#This Row],[CLIENTE]] & " */ Cont: * "&Tabla2[[#This Row],[CONTENEDOR]] & "*/ HR Entrega: *" & TEXT(Tabla2[[#This Row],[HORA ENTREGA]],"hh:mm") & "* /Dirección: *" & Tabla2[[#This Row],[Dirección Entrega]] -> Hola!%0AServicio del día 02-02%0A *Cliente:* IMPORTADORA Y COMERCIALIZADORA BZ SPA */ Cont: * MSMU5843771*/ HR Entrega: *11:00* /Dirección: *PuertoMadero 9710, Bodega X36. Pudahuel | AG28: =IFERROR(HYPERLINK("https://wa.me/"&Tabla2[[#This Row],[CONTACTO]]&"?text="&Tabla2[[#This Row],[Mensaje]],"Enviar mensaje"),"") -> Enviar mensaje | AH28: =CONCATENATE(A28,F28) -> 27MSMU5843771 | AI28: =CONCATENATE("ENT-",A28) -> ENT-27 | AJ28: =IF(Tabla2[[#This Row],[Op]]<>"","ENTREGA","") -> ENTREGA | AK28: =(Tabla2[[#This Row],[FECHA ENTREGA]]&Tabla2[[#This Row],[HORA ENTREGA]]) -> 460550,458333333333333 | AL28: =IFERROR(HYPERLINK("https://wa.me/"&Tabla2[[#This Row],[CONTACTO]]&"?text="&Tabla2[[#This Row],[Mensaje]]),"") -> https://wa.me/56944540732?text=Hola!%0AServicio del día 02-02%0A *Cliente:* IMPORTADORA Y COMERCIALIZADORA BZ SPA */ Cont: * MSMU5843771*/ HR Entrega: *11:00* /Dirección: *PuertoMadero 9710, Bodega X36. Pudahuel
A29: =ROW(A28) -> 28 | B29: =IF(J29=J28,B28+1,1) -> 27 | C29: IMPORTADORA Y COMERCIALIZADORA BZ SPA | D29: IMPO | E29: 871367 | F29: MEDU7395250 | G29: 40 HC | H29: 14000 | I29: MAIPU | J29: 46055 | K29: 0.5 | M29: JESUS GUTIERREZ | N29: =IFERROR(VLOOKUP(M29,Data!$J$1:$K$58,2,0),"") -> 56985215946 | O29: KPBC-56 | Q29: PuertoMadero 9710, Bodega X36. Pudahuel | R29: MEDLOG STGO | Y29: ENTREGADO | AA29: 0.52083333 | AC29: 46055 | AD29: =IF(Tabla2[[#This Row],[HORA ENTREGA]]="DIRECTO","On time", IF(AA29<>"",IF(Tabla2[[#This Row],[Fecha Real Entrega]]<Tabla2[[#This Row],[FECHA ENTREGA]],"On time",IF(Tabla2[[#This Row],[Hora Real Entrega]]<=Tabla2[[#This Row],[HORA ENTREGA]]+(15/1440),"On time","Off time")),"Sin llegada")) -> Off time | AE29: =MID(Tabla2[[#This Row],[TIPO]],1,3) -> 40 | AF29: ="Hola!" & "%0A" & "Servicio del día " &TEXT(Tabla2[[#This Row],[FECHA ENTREGA]],"dd-mm") & "%0A" & " *Cliente:* " &Tabla2[[#This Row],[CLIENTE]] & " */ Cont: * "&Tabla2[[#This Row],[CONTENEDOR]] & "*/ HR Entrega: *" & TEXT(Tabla2[[#This Row],[HORA ENTREGA]],"hh:mm") & "* /Dirección: *" & Tabla2[[#This Row],[Dirección Entrega]] -> Hola!%0AServicio del día 02-02%0A *Cliente:* IMPORTADORA Y COMERCIALIZADORA BZ SPA */ Cont: * MEDU7395250*/ HR Entrega: *12:00* /Dirección: *PuertoMadero 9710, Bodega X36. Pudahuel | AG29: =IFERROR(HYPERLINK("https://wa.me/"&Tabla2[[#This Row],[CONTACTO]]&"?text="&Tabla2[[#This Row],[Mensaje]],"Enviar mensaje"),"") -> Enviar mensaje | AH29: =CONCATENATE(A29,F29) -> 28MEDU7395250 | AI29: =CONCATENATE("ENT-",A29) -> ENT-28 | AJ29: =IF(Tabla2[[#This Row],[Op]]<>"","ENTREGA","") -> ENTREGA | AK29: =(Tabla2[[#This Row],[FECHA ENTREGA]]&Tabla2[[#This Row],[HORA ENTREGA]]) -> 460550,5 | AL29: =IFERROR(HYPERLINK("https://wa.me/"&Tabla2[[#This Row],[CONTACTO]]&"?text="&Tabla2[[#This Row],[Mensaje]]),"") -> https://wa.me/56985215946?text=Hola!%0AServicio del día 02-02%0A *Cliente:* IMPORTADORA Y COMERCIALIZADORA BZ SPA */ Cont: * MEDU7395250*/ HR Entrega: *12:00* /Dirección: *PuertoMadero 9710, Bodega X36. Pudahuel
A30: =ROW(A29) -> 29 | B30: =IF(J30=J29,B29+1,1) -> 28 | C30: IMPORTADORA Y COMERCIALIZADORA BZ SPA | D30: IMPO | E30: 871361 | F30: CAIU4870171 | G30: 40 FR | H30: 10000 | I30: FRAGUA | J30: 46055 | K30: 0.54166667 | M30: IVAN VASQUEZ URBINA | N30: =IFERROR(VLOOKUP(M30,Data!$J$1:$K$58,2,0),"") -> 56968463649 | O30: LGGR-12 | Q30: PuertoMadero 9710, Bodega X36. Pudahuel | R30: MEDLOG STGO | Y30: ENTREGADO | AA30: 0.67152778 | AC30: 46055 | AD30: =IF(Tabla2[[#This Row],[HORA ENTREGA]]="DIRECTO","On time", IF(AA30<>"",IF(Tabla2[[#This Row],[Fecha Real Entrega]]<Tabla2[[#This Row],[FECHA ENTREGA]],"On time",IF(Tabla2[[#This Row],[Hora Real Entrega]]<=Tabla2[[#This Row],[HORA ENTREGA]]+(15/1440),"On time","Off time")),"Sin llegada")) -> Off time | AE30: =MID(Tabla2[[#This Row],[TIPO]],1,3) -> 40 | AF30: ="Hola!" & "%0A" & "Servicio del día " &TEXT(Tabla2[[#This Row],[FECHA ENTREGA]],"dd-mm") & "%0A" & " *Cliente:* " &Tabla2[[#This Row],[CLIENTE]] & " */ Cont: * "&Tabla2[[#This Row],[CONTENEDOR]] & "*/ HR Entrega: *" & TEXT(Tabla2[[#This Row],[HORA ENTREGA]],"hh:mm") & "* /Dirección: *" & Tabla2[[#This Row],[Dirección Entrega]] -> Hola!%0AServicio del día 02-02%0A *Cliente:* IMPORTADORA Y COMERCIALIZADORA BZ SPA */ Cont: * CAIU4870171*/ HR Entrega: *13:00* /Dirección: *PuertoMadero 9710, Bodega X36. Pudahuel | AG30: =IFERROR(HYPERLINK("https://wa.me/"&Tabla2[[#This Row],[CONTACTO]]&"?text="&Tabla2[[#This Row],[Mensaje]],"Enviar mensaje"),"") -> Enviar mensaje | AH30: =CONCATENATE(A30,F30) -> 29CAIU4870171 | AI30: =CONCATENATE("ENT-",A30) -> ENT-29 | AJ30: =IF(Tabla2[[#This Row],[Op]]<>"","ENTREGA","") -> ENTREGA | AK30: =(Tabla2[[#This Row],[FECHA ENTREGA]]&Tabla2[[#This Row],[HORA ENTREGA]]) -> 460550,541666666666667 | AL30: =IFERROR(HYPERLINK("https://wa.me/"&Tabla2[[#This Row],[CONTACTO]]&"?text="&Tabla2[[#This Row],[Mensaje]]),"") -> https://wa.me/56968463649?text=Hola!%0AServicio del día 02-02%0A *Cliente:* IMPORTADORA Y COMERCIALIZADORA BZ SPA */ Cont: * CAIU4870171*/ HR Entrega: *13:00* /Dirección: *PuertoMadero 9710, Bodega X36. Pudahuel
